<robot name="magician">

    <!-- Defining the colors used in this robot -->
    <material name="Black">
        <color rgba="0 0 0 1"/>
    </material>

    <material name="White">
        <color rgba="1 1 1 1"/>
    </material>

    <material name="Grey">
        <color rgba="0.9 0.9 0.9 1"/>
    </material>

    <!--  -->
    <link name="base_link">
        <visual>
            <origin xyz="0 0 0" rpy="0 0 0"/>
            <geometry>
                <mesh filename="package://magician/meshes/base_link.STL"/>
            </geometry>
            <material name="White"/>
        </visual>
        <collision>
            <origin xyz="0 0 0" rpy="0 0 0"/>
            <geometry>
                <mesh filename="package://magician/meshes/base_link.STL"/>
            </geometry>
        </collision>
        <inertial>
            <origin rpy="0 0 0" xyz="0 0 0"/>
            <mass value="60.86397744"/>
            <inertia ixx="5.0635929" ixy="0.00103417" ixz="0.80199628" iyy="6.08689388" iyz="0.00105311" izz="4.96191932"/>
        </inertial>
    </link>

    <joint name="joint_1" type ="revolute">
        <origin xyz="0 0 0.024" rpy="0 0 0"/>
        <parent link="base_link"/>
        <child link="link_1"/>
        <axis xyz="0 0 1"/>
        <limit effort="150.0" lower="-3.14159265" upper="3.14159265" velocity="3.15"/>
    </joint>

    <link name="link_1">
        <visual>
            <origin xyz="0 0 0" rpy="0 0 0"/>
            <geometry>
                <mesh filename="package://magician/meshes/link_1.dae"/>
            </geometry>
            <!--material name="White"/-->
        </visual>
        <collision>
            <origin xyz="0 0 0" rpy="0 0 0"/>
            <geometry>
                <mesh filename="package://magician/meshes/link_1.STL"/>
            </geometry>
        </collision>
        <inertial>
           <origin rpy="0 0 0" xyz="-0.0006241 -2.8025E-05 0.065404"/>
           <mass value="2.0687"/>
           <inertia ixx="0.0067599" ixy="-4.2024E-05" ixz="-6.1904E-07" iyy="0.0067877" iyz="1.5888E-05" izz="0.0074031"/>
       </inertial>
    </link>

    
    <joint name="joint_2" type="revolute">
        <origin xyz="-0.01175 0 0.114" rpy="1.570796325 0 -1.570796325"/>
        <parent link="link_1"/>
        <child link="link_2"/>
        <axis xyz="0 0 1"/>
        <limit effort="150.0" lower="0" upper="1.570796325" velocity="3.15"/>
    </joint>

    <link name="link_2">
        <visual>
            <origin xyz="0 0 0" rpy="0 0 0"/>
            <geometry>
                <mesh filename="package://magician/meshes/link_2.dae"/>
            </geometry>
            <!--material name="Black"/-->
        </visual>
        <collision>
            <origin xyz="0 0 0" rpy="0 0 0"/>
            <geometry>
                <mesh filename="package://magician/meshes/link_2.STL"/>
            </geometry>
        </collision>
        <inertial>
          <origin rpy="0 0 0" xyz="0.024366 0.010969 0.14363"/>
          <mass value="5.3213"/>
          <inertia ixx="0.053314" ixy="0.0047093" ixz="0.011734" iyy="0.057902" iyz="0.0080179" izz="0.023659"/>
        </inertial>
    </link>
    
    <!--
    <joint name="joint_3" type ="revolute">
        <origin xyz="0.00475 0.00001 0.114" rpy="1.570796325 0 1.570796325"/>
        <parent link="link_1"/>
        <child link="link_3"/>
        <axis xyz="0 0 1"/>
        <limit effort="150.0" lower="-3.14159265" upper="3.14159265" velocity="3.15"/>
    </joint>
    -->

    <!--
    <link name="link_3">
        <visual>
            <origin xyz="0 0 0" rpy="0 0 0"/>
            <geometry>
                <mesh filename="package://magician/meshes/link_3.STL"/>
            </geometry>
        </visual>
        <collision>
            <origin xyz="0 0 0" rpy="0 0 0"/>
            <geometry>
                <mesh filename="package://magician/meshes/link_3.STL"/>
            </geometry>
        </collision>
    </link>
    -->
    
    <!--
    <joint name="joint_4" type ="revolute">
        <origin xyz="0.0013 0.042980 0.00275" rpy="0 -1.570796325 0"/>
        <parent link="link_3"/>
        <child link="link_4"/>
        <axis xyz="1 0 0"/>
        <limit effort="150.0" lower="-3.14159265" upper="3.14159265" velocity="3.15"/>
    </joint>
    -->

    <!--
    <link name="link_4">
        <visual>
            <origin xyz="0 0 0" rpy="0 0 0"/>
            <geometry>
                <mesh filename="package://magician/meshes/link_4.STL"/>
            </geometry>
        </visual>
        <collision>
            <origin xyz="0 0 0" rpy="0 0 0"/>
            <geometry>
                <mesh filename="package://magician/meshes/link_4.STL"/>
            </geometry>
        </collision>
        <inertial>
             <origin rpy="0 0 0" xyz="-0.00016232 -0.015346 0.13445"/>
             <mass value="1.7251"/>
             <inertia ixx="0.025176" ixy="4.3031E-06" ixz="1.4564E-05" iyy="0.024982" iyz="-0.0033928" izz="0.0033798"/>
        </inertial>
    </link>
    -->

    <joint name="joint_5" type ="revolute">
        <origin xyz="0.02699 0.13228 -0.01175" rpy="0 3.14159265 0"/>
        <parent link="link_2"/>
        <child link="link_5"/>
        <axis xyz="0 0 1"/>
        <limit effort="150.0" lower="0" upper="1.570796325" velocity="3.15"/>
    </joint>

    <link name="link_5">
        <visual>
            <origin xyz="0 0 0" rpy="0 0 0"/>
            <geometry>
                <mesh filename="package://magician/meshes/link_5.dae"/>
            </geometry>
            <!-- material name="White"/-->
        </visual>
        <collision>
            <origin xyz="0 0 0" rpy="0 0 0"/>
            <geometry>
                <mesh filename="package://magician/meshes/link_5.dae"/>
            </geometry>
        </collision>
        <inertial>
            <origin rpy="0 0 0" xyz="-0.0027794 0.0076558 0.13273"/>
            <mass value="1.0433"/>
            <inertia ixx="0.012913" ixy="2.573E-05" ixz="0.00017705" iyy="0.012939" iyz="0.0011152" izz="0.0012405"/>
        </inertial>
    </link>

    <joint name="joint_6" type ="revolute">
        <origin xyz="0.07431 -0.12684 0.0" rpy="0 3.14159265 0"/>
        <parent link="link_5"/>
        <child link="link_6"/>
        <axis xyz="0 0 1"/>
        <limit effort="150.0" lower="-3.14159265" upper="3.14159265" velocity="3.15"/>

    </joint>

    <link name="link_6">
        <visual>
            <origin xyz="0 0 0" rpy="0 0 0"/>
            <geometry>
                <mesh filename="package://magician/meshes/link_6.STL"/>
            </geometry>
            <material name="Grey"/>
        </visual>
        <collision>
            <origin xyz="0 0 0" rpy="0 0 0"/>
            <geometry>
                <mesh filename="package://magician/meshes/link_6.STL"/>
            </geometry>
        </collision>
        <inertial>
             <origin rpy="0 0 0" xyz="0.0062067 -0.024291 0.075564"/>
             <mass value="1.5343"/>
             <inertia ixx="0.0046072" ixy="0.00012002" ixz="5.3065E-05" iyy="0.0028725" iyz="-0.0011886" izz="0.003101"/>
        </inertial>
    </link>

    <!--dummy joint-->
    <joint name="joint_7" type ="revolute">
        <origin xyz="-0.0328 0.02871 0" rpy="0 3.14159265 0"/>
        <parent link="link_6"/>
        <child link="link_7"/>
        <axis xyz="0 0 1"/>
        <limit effort="150.0" lower="-3.14159265" upper="3.14159265" velocity="3.15"/>
        
    </joint>

    <link name="link_7">
        <visual>
            <origin xyz="0 0 0" rpy="0 0 0"/>
            <geometry>
                <mesh filename="package://magician/meshes/link_7.STL"/>
            </geometry>
            <material name="Black"/>
        </visual>
        <collision>
            <origin xyz="0 0 0" rpy="0 0 0"/>
            <geometry>
                <mesh filename="package://magician/meshes/link_7.STL"/>
            </geometry>
        </collision>
        <inertial>
             <origin rpy="0 0 0" xyz="-8.0726E-06 0.0085838 -0.0049566"/>
             <mass value="0.3292"/>
             <inertia ixx="0.00031105" ixy="1.4771E-06" ixz="-3.7074E-07" iyy="0.00021549" iyz="-8.4533E-06" izz="0.00035976"/>
        </inertial>
    </link>
    

</robot>  